{
 "cells": [
  {
   "cell_type": "code",
   "execution_count": 1,
   "metadata": {
    "collapsed": true
   },
   "outputs": [],
   "source": [
    "import boto3"
   ]
  },
  {
   "cell_type": "code",
   "execution_count": 2,
   "metadata": {
    "collapsed": true
   },
   "outputs": [],
   "source": [
    "credentials_path=\"client/credentials.json\""
   ]
  },
  {
   "cell_type": "code",
   "execution_count": 5,
   "metadata": {
    "collapsed": true
   },
   "outputs": [],
   "source": [
    "filepath = credentials_path\n",
    "sb_credentials = json.load(open(filepath))"
   ]
  },
  {
   "cell_type": "code",
   "execution_count": 29,
   "metadata": {},
   "outputs": [],
   "source": [
    "s = boto3.Session(aws_access_key_id=sb_credentials['s3accessKeys']['AWS_ACCESS_KEY_ID'],\n",
    "    aws_secret_access_key=sb_credentials['s3accessKeys']['AWS_SECRET_ACCESS_KEY'], region_name)"
   ]
  },
  {
   "cell_type": "code",
   "execution_count": 30,
   "metadata": {},
   "outputs": [],
   "source": [
    "t = s.client('s3')"
   ]
  },
  {
   "cell_type": "code",
   "execution_count": 23,
   "metadata": {},
   "outputs": [
    {
     "ename": "EndpointConnectionError",
     "evalue": "Could not connect to the endpoint URL: \"https://s3.ireland.amazonaws.com/ai-sony-automation?list-type=2\"",
     "output_type": "error",
     "traceback": [
      "\u001b[0;31m---------------------------------------------------------------------------\u001b[0m",
      "\u001b[0;31mEndpointConnectionError\u001b[0m                   Traceback (most recent call last)",
      "\u001b[0;32m<ipython-input-23-820a5864580b>\u001b[0m in \u001b[0;36m<module>\u001b[0;34m()\u001b[0m\n\u001b[0;32m----> 1\u001b[0;31m \u001b[0mt\u001b[0m\u001b[0;34m.\u001b[0m\u001b[0mlist_objects_v2\u001b[0m\u001b[0;34m(\u001b[0m\u001b[0mBucket\u001b[0m\u001b[0;34m=\u001b[0m\u001b[0;34m'ai-sony-automation'\u001b[0m\u001b[0;34m)\u001b[0m\u001b[0;34m\u001b[0m\u001b[0m\n\u001b[0m",
      "\u001b[0;32m/Users/aymericflaisler/anaconda2/envs/py27conda/lib/python2.7/site-packages/botocore/client.pyc\u001b[0m in \u001b[0;36m_api_call\u001b[0;34m(self, *args, **kwargs)\u001b[0m\n\u001b[1;32m    315\u001b[0m                     \"%s() only accepts keyword arguments.\" % py_operation_name)\n\u001b[1;32m    316\u001b[0m             \u001b[0;31m# The \"self\" in this scope is referring to the BaseClient.\u001b[0m\u001b[0;34m\u001b[0m\u001b[0;34m\u001b[0m\u001b[0m\n\u001b[0;32m--> 317\u001b[0;31m             \u001b[0;32mreturn\u001b[0m \u001b[0mself\u001b[0m\u001b[0;34m.\u001b[0m\u001b[0m_make_api_call\u001b[0m\u001b[0;34m(\u001b[0m\u001b[0moperation_name\u001b[0m\u001b[0;34m,\u001b[0m \u001b[0mkwargs\u001b[0m\u001b[0;34m)\u001b[0m\u001b[0;34m\u001b[0m\u001b[0m\n\u001b[0m\u001b[1;32m    318\u001b[0m \u001b[0;34m\u001b[0m\u001b[0m\n\u001b[1;32m    319\u001b[0m         \u001b[0m_api_call\u001b[0m\u001b[0;34m.\u001b[0m\u001b[0m__name__\u001b[0m \u001b[0;34m=\u001b[0m \u001b[0mstr\u001b[0m\u001b[0;34m(\u001b[0m\u001b[0mpy_operation_name\u001b[0m\u001b[0;34m)\u001b[0m\u001b[0;34m\u001b[0m\u001b[0m\n",
      "\u001b[0;32m/Users/aymericflaisler/anaconda2/envs/py27conda/lib/python2.7/site-packages/botocore/client.pyc\u001b[0m in \u001b[0;36m_make_api_call\u001b[0;34m(self, operation_name, api_params)\u001b[0m\n\u001b[1;32m    600\u001b[0m         \u001b[0;32melse\u001b[0m\u001b[0;34m:\u001b[0m\u001b[0;34m\u001b[0m\u001b[0m\n\u001b[1;32m    601\u001b[0m             http, parsed_response = self._endpoint.make_request(\n\u001b[0;32m--> 602\u001b[0;31m                 operation_model, request_dict)\n\u001b[0m\u001b[1;32m    603\u001b[0m \u001b[0;34m\u001b[0m\u001b[0m\n\u001b[1;32m    604\u001b[0m         self.meta.events.emit(\n",
      "\u001b[0;32m/Users/aymericflaisler/anaconda2/envs/py27conda/lib/python2.7/site-packages/botocore/endpoint.pyc\u001b[0m in \u001b[0;36mmake_request\u001b[0;34m(self, operation_model, request_dict)\u001b[0m\n\u001b[1;32m    141\u001b[0m         logger.debug(\"Making request for %s (verify_ssl=%s) with params: %s\",\n\u001b[1;32m    142\u001b[0m                      operation_model, self.verify, request_dict)\n\u001b[0;32m--> 143\u001b[0;31m         \u001b[0;32mreturn\u001b[0m \u001b[0mself\u001b[0m\u001b[0;34m.\u001b[0m\u001b[0m_send_request\u001b[0m\u001b[0;34m(\u001b[0m\u001b[0mrequest_dict\u001b[0m\u001b[0;34m,\u001b[0m \u001b[0moperation_model\u001b[0m\u001b[0;34m)\u001b[0m\u001b[0;34m\u001b[0m\u001b[0m\n\u001b[0m\u001b[1;32m    144\u001b[0m \u001b[0;34m\u001b[0m\u001b[0m\n\u001b[1;32m    145\u001b[0m     \u001b[0;32mdef\u001b[0m \u001b[0mcreate_request\u001b[0m\u001b[0;34m(\u001b[0m\u001b[0mself\u001b[0m\u001b[0;34m,\u001b[0m \u001b[0mparams\u001b[0m\u001b[0;34m,\u001b[0m \u001b[0moperation_model\u001b[0m\u001b[0;34m=\u001b[0m\u001b[0mNone\u001b[0m\u001b[0;34m)\u001b[0m\u001b[0;34m:\u001b[0m\u001b[0;34m\u001b[0m\u001b[0m\n",
      "\u001b[0;32m/Users/aymericflaisler/anaconda2/envs/py27conda/lib/python2.7/site-packages/botocore/endpoint.pyc\u001b[0m in \u001b[0;36m_send_request\u001b[0;34m(self, request_dict, operation_model)\u001b[0m\n\u001b[1;32m    170\u001b[0m             request, operation_model, attempts)\n\u001b[1;32m    171\u001b[0m         while self._needs_retry(attempts, operation_model, request_dict,\n\u001b[0;32m--> 172\u001b[0;31m                                 success_response, exception):\n\u001b[0m\u001b[1;32m    173\u001b[0m             \u001b[0mattempts\u001b[0m \u001b[0;34m+=\u001b[0m \u001b[0;36m1\u001b[0m\u001b[0;34m\u001b[0m\u001b[0m\n\u001b[1;32m    174\u001b[0m             \u001b[0;31m# If there is a stream associated with the request, we need\u001b[0m\u001b[0;34m\u001b[0m\u001b[0;34m\u001b[0m\u001b[0m\n",
      "\u001b[0;32m/Users/aymericflaisler/anaconda2/envs/py27conda/lib/python2.7/site-packages/botocore/endpoint.pyc\u001b[0m in \u001b[0;36m_needs_retry\u001b[0;34m(self, attempts, operation_model, request_dict, response, caught_exception)\u001b[0m\n\u001b[1;32m    263\u001b[0m             \u001b[0mevent_name\u001b[0m\u001b[0;34m,\u001b[0m \u001b[0mresponse\u001b[0m\u001b[0;34m=\u001b[0m\u001b[0mresponse\u001b[0m\u001b[0;34m,\u001b[0m \u001b[0mendpoint\u001b[0m\u001b[0;34m=\u001b[0m\u001b[0mself\u001b[0m\u001b[0;34m,\u001b[0m\u001b[0;34m\u001b[0m\u001b[0m\n\u001b[1;32m    264\u001b[0m             \u001b[0moperation\u001b[0m\u001b[0;34m=\u001b[0m\u001b[0moperation_model\u001b[0m\u001b[0;34m,\u001b[0m \u001b[0mattempts\u001b[0m\u001b[0;34m=\u001b[0m\u001b[0mattempts\u001b[0m\u001b[0;34m,\u001b[0m\u001b[0;34m\u001b[0m\u001b[0m\n\u001b[0;32m--> 265\u001b[0;31m             caught_exception=caught_exception, request_dict=request_dict)\n\u001b[0m\u001b[1;32m    266\u001b[0m         \u001b[0mhandler_response\u001b[0m \u001b[0;34m=\u001b[0m \u001b[0mfirst_non_none_response\u001b[0m\u001b[0;34m(\u001b[0m\u001b[0mresponses\u001b[0m\u001b[0;34m)\u001b[0m\u001b[0;34m\u001b[0m\u001b[0m\n\u001b[1;32m    267\u001b[0m         \u001b[0;32mif\u001b[0m \u001b[0mhandler_response\u001b[0m \u001b[0;32mis\u001b[0m \u001b[0mNone\u001b[0m\u001b[0;34m:\u001b[0m\u001b[0;34m\u001b[0m\u001b[0m\n",
      "\u001b[0;32m/Users/aymericflaisler/anaconda2/envs/py27conda/lib/python2.7/site-packages/botocore/hooks.pyc\u001b[0m in \u001b[0;36memit\u001b[0;34m(self, event_name, **kwargs)\u001b[0m\n\u001b[1;32m    225\u001b[0m                  \u001b[0mhandlers\u001b[0m\u001b[0;34m.\u001b[0m\u001b[0;34m\u001b[0m\u001b[0m\n\u001b[1;32m    226\u001b[0m         \"\"\"\n\u001b[0;32m--> 227\u001b[0;31m         \u001b[0;32mreturn\u001b[0m \u001b[0mself\u001b[0m\u001b[0;34m.\u001b[0m\u001b[0m_emit\u001b[0m\u001b[0;34m(\u001b[0m\u001b[0mevent_name\u001b[0m\u001b[0;34m,\u001b[0m \u001b[0mkwargs\u001b[0m\u001b[0;34m)\u001b[0m\u001b[0;34m\u001b[0m\u001b[0m\n\u001b[0m\u001b[1;32m    228\u001b[0m \u001b[0;34m\u001b[0m\u001b[0m\n\u001b[1;32m    229\u001b[0m     \u001b[0;32mdef\u001b[0m \u001b[0memit_until_response\u001b[0m\u001b[0;34m(\u001b[0m\u001b[0mself\u001b[0m\u001b[0;34m,\u001b[0m \u001b[0mevent_name\u001b[0m\u001b[0;34m,\u001b[0m \u001b[0;34m**\u001b[0m\u001b[0mkwargs\u001b[0m\u001b[0;34m)\u001b[0m\u001b[0;34m:\u001b[0m\u001b[0;34m\u001b[0m\u001b[0m\n",
      "\u001b[0;32m/Users/aymericflaisler/anaconda2/envs/py27conda/lib/python2.7/site-packages/botocore/hooks.pyc\u001b[0m in \u001b[0;36m_emit\u001b[0;34m(self, event_name, kwargs, stop_on_response)\u001b[0m\n\u001b[1;32m    208\u001b[0m         \u001b[0;32mfor\u001b[0m \u001b[0mhandler\u001b[0m \u001b[0;32min\u001b[0m \u001b[0mhandlers_to_call\u001b[0m\u001b[0;34m:\u001b[0m\u001b[0;34m\u001b[0m\u001b[0m\n\u001b[1;32m    209\u001b[0m             \u001b[0mlogger\u001b[0m\u001b[0;34m.\u001b[0m\u001b[0mdebug\u001b[0m\u001b[0;34m(\u001b[0m\u001b[0;34m'Event %s: calling handler %s'\u001b[0m\u001b[0;34m,\u001b[0m \u001b[0mevent_name\u001b[0m\u001b[0;34m,\u001b[0m \u001b[0mhandler\u001b[0m\u001b[0;34m)\u001b[0m\u001b[0;34m\u001b[0m\u001b[0m\n\u001b[0;32m--> 210\u001b[0;31m             \u001b[0mresponse\u001b[0m \u001b[0;34m=\u001b[0m \u001b[0mhandler\u001b[0m\u001b[0;34m(\u001b[0m\u001b[0;34m**\u001b[0m\u001b[0mkwargs\u001b[0m\u001b[0;34m)\u001b[0m\u001b[0;34m\u001b[0m\u001b[0m\n\u001b[0m\u001b[1;32m    211\u001b[0m             \u001b[0mresponses\u001b[0m\u001b[0;34m.\u001b[0m\u001b[0mappend\u001b[0m\u001b[0;34m(\u001b[0m\u001b[0;34m(\u001b[0m\u001b[0mhandler\u001b[0m\u001b[0;34m,\u001b[0m \u001b[0mresponse\u001b[0m\u001b[0;34m)\u001b[0m\u001b[0;34m)\u001b[0m\u001b[0;34m\u001b[0m\u001b[0m\n\u001b[1;32m    212\u001b[0m             \u001b[0;32mif\u001b[0m \u001b[0mstop_on_response\u001b[0m \u001b[0;32mand\u001b[0m \u001b[0mresponse\u001b[0m \u001b[0;32mis\u001b[0m \u001b[0;32mnot\u001b[0m \u001b[0mNone\u001b[0m\u001b[0;34m:\u001b[0m\u001b[0;34m\u001b[0m\u001b[0m\n",
      "\u001b[0;32m/Users/aymericflaisler/anaconda2/envs/py27conda/lib/python2.7/site-packages/botocore/retryhandler.pyc\u001b[0m in \u001b[0;36m__call__\u001b[0;34m(self, attempts, response, caught_exception, **kwargs)\u001b[0m\n\u001b[1;32m    181\u001b[0m \u001b[0;34m\u001b[0m\u001b[0m\n\u001b[1;32m    182\u001b[0m         \"\"\"\n\u001b[0;32m--> 183\u001b[0;31m         \u001b[0;32mif\u001b[0m \u001b[0mself\u001b[0m\u001b[0;34m.\u001b[0m\u001b[0m_checker\u001b[0m\u001b[0;34m(\u001b[0m\u001b[0mattempts\u001b[0m\u001b[0;34m,\u001b[0m \u001b[0mresponse\u001b[0m\u001b[0;34m,\u001b[0m \u001b[0mcaught_exception\u001b[0m\u001b[0;34m)\u001b[0m\u001b[0;34m:\u001b[0m\u001b[0;34m\u001b[0m\u001b[0m\n\u001b[0m\u001b[1;32m    184\u001b[0m             \u001b[0mresult\u001b[0m \u001b[0;34m=\u001b[0m \u001b[0mself\u001b[0m\u001b[0;34m.\u001b[0m\u001b[0m_action\u001b[0m\u001b[0;34m(\u001b[0m\u001b[0mattempts\u001b[0m\u001b[0;34m=\u001b[0m\u001b[0mattempts\u001b[0m\u001b[0;34m)\u001b[0m\u001b[0;34m\u001b[0m\u001b[0m\n\u001b[1;32m    185\u001b[0m             \u001b[0mlogger\u001b[0m\u001b[0;34m.\u001b[0m\u001b[0mdebug\u001b[0m\u001b[0;34m(\u001b[0m\u001b[0;34m\"Retry needed, action of: %s\"\u001b[0m\u001b[0;34m,\u001b[0m \u001b[0mresult\u001b[0m\u001b[0;34m)\u001b[0m\u001b[0;34m\u001b[0m\u001b[0m\n",
      "\u001b[0;32m/Users/aymericflaisler/anaconda2/envs/py27conda/lib/python2.7/site-packages/botocore/retryhandler.pyc\u001b[0m in \u001b[0;36m__call__\u001b[0;34m(self, attempt_number, response, caught_exception)\u001b[0m\n\u001b[1;32m    249\u001b[0m     \u001b[0;32mdef\u001b[0m \u001b[0m__call__\u001b[0m\u001b[0;34m(\u001b[0m\u001b[0mself\u001b[0m\u001b[0;34m,\u001b[0m \u001b[0mattempt_number\u001b[0m\u001b[0;34m,\u001b[0m \u001b[0mresponse\u001b[0m\u001b[0;34m,\u001b[0m \u001b[0mcaught_exception\u001b[0m\u001b[0;34m)\u001b[0m\u001b[0;34m:\u001b[0m\u001b[0;34m\u001b[0m\u001b[0m\n\u001b[1;32m    250\u001b[0m         should_retry = self._should_retry(attempt_number, response,\n\u001b[0;32m--> 251\u001b[0;31m                                           caught_exception)\n\u001b[0m\u001b[1;32m    252\u001b[0m         \u001b[0;32mif\u001b[0m \u001b[0mshould_retry\u001b[0m\u001b[0;34m:\u001b[0m\u001b[0;34m\u001b[0m\u001b[0m\n\u001b[1;32m    253\u001b[0m             \u001b[0;32mif\u001b[0m \u001b[0mattempt_number\u001b[0m \u001b[0;34m>=\u001b[0m \u001b[0mself\u001b[0m\u001b[0;34m.\u001b[0m\u001b[0m_max_attempts\u001b[0m\u001b[0;34m:\u001b[0m\u001b[0;34m\u001b[0m\u001b[0m\n",
      "\u001b[0;32m/Users/aymericflaisler/anaconda2/envs/py27conda/lib/python2.7/site-packages/botocore/retryhandler.pyc\u001b[0m in \u001b[0;36m_should_retry\u001b[0;34m(self, attempt_number, response, caught_exception)\u001b[0m\n\u001b[1;32m    275\u001b[0m             \u001b[0;31m# If we've exceeded the max attempts we just let the exception\u001b[0m\u001b[0;34m\u001b[0m\u001b[0;34m\u001b[0m\u001b[0m\n\u001b[1;32m    276\u001b[0m             \u001b[0;31m# propogate if one has occurred.\u001b[0m\u001b[0;34m\u001b[0m\u001b[0;34m\u001b[0m\u001b[0m\n\u001b[0;32m--> 277\u001b[0;31m             \u001b[0;32mreturn\u001b[0m \u001b[0mself\u001b[0m\u001b[0;34m.\u001b[0m\u001b[0m_checker\u001b[0m\u001b[0;34m(\u001b[0m\u001b[0mattempt_number\u001b[0m\u001b[0;34m,\u001b[0m \u001b[0mresponse\u001b[0m\u001b[0;34m,\u001b[0m \u001b[0mcaught_exception\u001b[0m\u001b[0;34m)\u001b[0m\u001b[0;34m\u001b[0m\u001b[0m\n\u001b[0m\u001b[1;32m    278\u001b[0m \u001b[0;34m\u001b[0m\u001b[0m\n\u001b[1;32m    279\u001b[0m \u001b[0;34m\u001b[0m\u001b[0m\n",
      "\u001b[0;32m/Users/aymericflaisler/anaconda2/envs/py27conda/lib/python2.7/site-packages/botocore/retryhandler.pyc\u001b[0m in \u001b[0;36m__call__\u001b[0;34m(self, attempt_number, response, caught_exception)\u001b[0m\n\u001b[1;32m    315\u001b[0m         \u001b[0;32mfor\u001b[0m \u001b[0mchecker\u001b[0m \u001b[0;32min\u001b[0m \u001b[0mself\u001b[0m\u001b[0;34m.\u001b[0m\u001b[0m_checkers\u001b[0m\u001b[0;34m:\u001b[0m\u001b[0;34m\u001b[0m\u001b[0m\n\u001b[1;32m    316\u001b[0m             checker_response = checker(attempt_number, response,\n\u001b[0;32m--> 317\u001b[0;31m                                        caught_exception)\n\u001b[0m\u001b[1;32m    318\u001b[0m             \u001b[0;32mif\u001b[0m \u001b[0mchecker_response\u001b[0m\u001b[0;34m:\u001b[0m\u001b[0;34m\u001b[0m\u001b[0m\n\u001b[1;32m    319\u001b[0m                 \u001b[0;32mreturn\u001b[0m \u001b[0mchecker_response\u001b[0m\u001b[0;34m\u001b[0m\u001b[0m\n",
      "\u001b[0;32m/Users/aymericflaisler/anaconda2/envs/py27conda/lib/python2.7/site-packages/botocore/retryhandler.pyc\u001b[0m in \u001b[0;36m__call__\u001b[0;34m(self, attempt_number, response, caught_exception)\u001b[0m\n\u001b[1;32m    221\u001b[0m         \u001b[0;32melif\u001b[0m \u001b[0mcaught_exception\u001b[0m \u001b[0;32mis\u001b[0m \u001b[0;32mnot\u001b[0m \u001b[0mNone\u001b[0m\u001b[0;34m:\u001b[0m\u001b[0;34m\u001b[0m\u001b[0m\n\u001b[1;32m    222\u001b[0m             return self._check_caught_exception(\n\u001b[0;32m--> 223\u001b[0;31m                 attempt_number, caught_exception)\n\u001b[0m\u001b[1;32m    224\u001b[0m         \u001b[0;32melse\u001b[0m\u001b[0;34m:\u001b[0m\u001b[0;34m\u001b[0m\u001b[0m\n\u001b[1;32m    225\u001b[0m             \u001b[0;32mraise\u001b[0m \u001b[0mValueError\u001b[0m\u001b[0;34m(\u001b[0m\u001b[0;34m\"Both response and caught_exception are None.\"\u001b[0m\u001b[0;34m)\u001b[0m\u001b[0;34m\u001b[0m\u001b[0m\n",
      "\u001b[0;32m/Users/aymericflaisler/anaconda2/envs/py27conda/lib/python2.7/site-packages/botocore/retryhandler.pyc\u001b[0m in \u001b[0;36m_check_caught_exception\u001b[0;34m(self, attempt_number, caught_exception)\u001b[0m\n\u001b[1;32m    357\u001b[0m         \u001b[0;31m# the MaxAttemptsDecorator is not interested in retrying the exception\u001b[0m\u001b[0;34m\u001b[0m\u001b[0;34m\u001b[0m\u001b[0m\n\u001b[1;32m    358\u001b[0m         \u001b[0;31m# then this exception just propogates out past the retry code.\u001b[0m\u001b[0;34m\u001b[0m\u001b[0;34m\u001b[0m\u001b[0m\n\u001b[0;32m--> 359\u001b[0;31m         \u001b[0;32mraise\u001b[0m \u001b[0mcaught_exception\u001b[0m\u001b[0;34m\u001b[0m\u001b[0m\n\u001b[0m",
      "\u001b[0;31mEndpointConnectionError\u001b[0m: Could not connect to the endpoint URL: \"https://s3.ireland.amazonaws.com/ai-sony-automation?list-type=2\""
     ]
    }
   ],
   "source": [
    "t.list_objects_v2(Bucket='ai-sony-automation')"
   ]
  },
  {
   "cell_type": "code",
   "execution_count": 28,
   "metadata": {},
   "outputs": [
    {
     "ename": "EndpointConnectionError",
     "evalue": "Could not connect to the endpoint URL: \"https://s3.ireland.amazonaws.com/ai-sony-automation?encoding-type=url\"",
     "output_type": "error",
     "traceback": [
      "\u001b[0;31m---------------------------------------------------------------------------\u001b[0m",
      "\u001b[0;31mEndpointConnectionError\u001b[0m                   Traceback (most recent call last)",
      "\u001b[0;32m<ipython-input-28-c4a302a938b9>\u001b[0m in \u001b[0;36m<module>\u001b[0;34m()\u001b[0m\n\u001b[0;32m----> 1\u001b[0;31m \u001b[0mt\u001b[0m\u001b[0;34m.\u001b[0m\u001b[0mlist_objects\u001b[0m\u001b[0;34m(\u001b[0m\u001b[0mBucket\u001b[0m\u001b[0;34m=\u001b[0m\u001b[0;34m'ai-sony-automation'\u001b[0m\u001b[0;34m)\u001b[0m\u001b[0;34m\u001b[0m\u001b[0m\n\u001b[0m",
      "\u001b[0;32m/Users/aymericflaisler/anaconda2/envs/py27conda/lib/python2.7/site-packages/botocore/client.pyc\u001b[0m in \u001b[0;36m_api_call\u001b[0;34m(self, *args, **kwargs)\u001b[0m\n\u001b[1;32m    315\u001b[0m                     \"%s() only accepts keyword arguments.\" % py_operation_name)\n\u001b[1;32m    316\u001b[0m             \u001b[0;31m# The \"self\" in this scope is referring to the BaseClient.\u001b[0m\u001b[0;34m\u001b[0m\u001b[0;34m\u001b[0m\u001b[0m\n\u001b[0;32m--> 317\u001b[0;31m             \u001b[0;32mreturn\u001b[0m \u001b[0mself\u001b[0m\u001b[0;34m.\u001b[0m\u001b[0m_make_api_call\u001b[0m\u001b[0;34m(\u001b[0m\u001b[0moperation_name\u001b[0m\u001b[0;34m,\u001b[0m \u001b[0mkwargs\u001b[0m\u001b[0;34m)\u001b[0m\u001b[0;34m\u001b[0m\u001b[0m\n\u001b[0m\u001b[1;32m    318\u001b[0m \u001b[0;34m\u001b[0m\u001b[0m\n\u001b[1;32m    319\u001b[0m         \u001b[0m_api_call\u001b[0m\u001b[0;34m.\u001b[0m\u001b[0m__name__\u001b[0m \u001b[0;34m=\u001b[0m \u001b[0mstr\u001b[0m\u001b[0;34m(\u001b[0m\u001b[0mpy_operation_name\u001b[0m\u001b[0;34m)\u001b[0m\u001b[0;34m\u001b[0m\u001b[0m\n",
      "\u001b[0;32m/Users/aymericflaisler/anaconda2/envs/py27conda/lib/python2.7/site-packages/botocore/client.pyc\u001b[0m in \u001b[0;36m_make_api_call\u001b[0;34m(self, operation_name, api_params)\u001b[0m\n\u001b[1;32m    600\u001b[0m         \u001b[0;32melse\u001b[0m\u001b[0;34m:\u001b[0m\u001b[0;34m\u001b[0m\u001b[0m\n\u001b[1;32m    601\u001b[0m             http, parsed_response = self._endpoint.make_request(\n\u001b[0;32m--> 602\u001b[0;31m                 operation_model, request_dict)\n\u001b[0m\u001b[1;32m    603\u001b[0m \u001b[0;34m\u001b[0m\u001b[0m\n\u001b[1;32m    604\u001b[0m         self.meta.events.emit(\n",
      "\u001b[0;32m/Users/aymericflaisler/anaconda2/envs/py27conda/lib/python2.7/site-packages/botocore/endpoint.pyc\u001b[0m in \u001b[0;36mmake_request\u001b[0;34m(self, operation_model, request_dict)\u001b[0m\n\u001b[1;32m    141\u001b[0m         logger.debug(\"Making request for %s (verify_ssl=%s) with params: %s\",\n\u001b[1;32m    142\u001b[0m                      operation_model, self.verify, request_dict)\n\u001b[0;32m--> 143\u001b[0;31m         \u001b[0;32mreturn\u001b[0m \u001b[0mself\u001b[0m\u001b[0;34m.\u001b[0m\u001b[0m_send_request\u001b[0m\u001b[0;34m(\u001b[0m\u001b[0mrequest_dict\u001b[0m\u001b[0;34m,\u001b[0m \u001b[0moperation_model\u001b[0m\u001b[0;34m)\u001b[0m\u001b[0;34m\u001b[0m\u001b[0m\n\u001b[0m\u001b[1;32m    144\u001b[0m \u001b[0;34m\u001b[0m\u001b[0m\n\u001b[1;32m    145\u001b[0m     \u001b[0;32mdef\u001b[0m \u001b[0mcreate_request\u001b[0m\u001b[0;34m(\u001b[0m\u001b[0mself\u001b[0m\u001b[0;34m,\u001b[0m \u001b[0mparams\u001b[0m\u001b[0;34m,\u001b[0m \u001b[0moperation_model\u001b[0m\u001b[0;34m=\u001b[0m\u001b[0mNone\u001b[0m\u001b[0;34m)\u001b[0m\u001b[0;34m:\u001b[0m\u001b[0;34m\u001b[0m\u001b[0m\n",
      "\u001b[0;32m/Users/aymericflaisler/anaconda2/envs/py27conda/lib/python2.7/site-packages/botocore/endpoint.pyc\u001b[0m in \u001b[0;36m_send_request\u001b[0;34m(self, request_dict, operation_model)\u001b[0m\n\u001b[1;32m    170\u001b[0m             request, operation_model, attempts)\n\u001b[1;32m    171\u001b[0m         while self._needs_retry(attempts, operation_model, request_dict,\n\u001b[0;32m--> 172\u001b[0;31m                                 success_response, exception):\n\u001b[0m\u001b[1;32m    173\u001b[0m             \u001b[0mattempts\u001b[0m \u001b[0;34m+=\u001b[0m \u001b[0;36m1\u001b[0m\u001b[0;34m\u001b[0m\u001b[0m\n\u001b[1;32m    174\u001b[0m             \u001b[0;31m# If there is a stream associated with the request, we need\u001b[0m\u001b[0;34m\u001b[0m\u001b[0;34m\u001b[0m\u001b[0m\n",
      "\u001b[0;32m/Users/aymericflaisler/anaconda2/envs/py27conda/lib/python2.7/site-packages/botocore/endpoint.pyc\u001b[0m in \u001b[0;36m_needs_retry\u001b[0;34m(self, attempts, operation_model, request_dict, response, caught_exception)\u001b[0m\n\u001b[1;32m    263\u001b[0m             \u001b[0mevent_name\u001b[0m\u001b[0;34m,\u001b[0m \u001b[0mresponse\u001b[0m\u001b[0;34m=\u001b[0m\u001b[0mresponse\u001b[0m\u001b[0;34m,\u001b[0m \u001b[0mendpoint\u001b[0m\u001b[0;34m=\u001b[0m\u001b[0mself\u001b[0m\u001b[0;34m,\u001b[0m\u001b[0;34m\u001b[0m\u001b[0m\n\u001b[1;32m    264\u001b[0m             \u001b[0moperation\u001b[0m\u001b[0;34m=\u001b[0m\u001b[0moperation_model\u001b[0m\u001b[0;34m,\u001b[0m \u001b[0mattempts\u001b[0m\u001b[0;34m=\u001b[0m\u001b[0mattempts\u001b[0m\u001b[0;34m,\u001b[0m\u001b[0;34m\u001b[0m\u001b[0m\n\u001b[0;32m--> 265\u001b[0;31m             caught_exception=caught_exception, request_dict=request_dict)\n\u001b[0m\u001b[1;32m    266\u001b[0m         \u001b[0mhandler_response\u001b[0m \u001b[0;34m=\u001b[0m \u001b[0mfirst_non_none_response\u001b[0m\u001b[0;34m(\u001b[0m\u001b[0mresponses\u001b[0m\u001b[0;34m)\u001b[0m\u001b[0;34m\u001b[0m\u001b[0m\n\u001b[1;32m    267\u001b[0m         \u001b[0;32mif\u001b[0m \u001b[0mhandler_response\u001b[0m \u001b[0;32mis\u001b[0m \u001b[0mNone\u001b[0m\u001b[0;34m:\u001b[0m\u001b[0;34m\u001b[0m\u001b[0m\n",
      "\u001b[0;32m/Users/aymericflaisler/anaconda2/envs/py27conda/lib/python2.7/site-packages/botocore/hooks.pyc\u001b[0m in \u001b[0;36memit\u001b[0;34m(self, event_name, **kwargs)\u001b[0m\n\u001b[1;32m    225\u001b[0m                  \u001b[0mhandlers\u001b[0m\u001b[0;34m.\u001b[0m\u001b[0;34m\u001b[0m\u001b[0m\n\u001b[1;32m    226\u001b[0m         \"\"\"\n\u001b[0;32m--> 227\u001b[0;31m         \u001b[0;32mreturn\u001b[0m \u001b[0mself\u001b[0m\u001b[0;34m.\u001b[0m\u001b[0m_emit\u001b[0m\u001b[0;34m(\u001b[0m\u001b[0mevent_name\u001b[0m\u001b[0;34m,\u001b[0m \u001b[0mkwargs\u001b[0m\u001b[0;34m)\u001b[0m\u001b[0;34m\u001b[0m\u001b[0m\n\u001b[0m\u001b[1;32m    228\u001b[0m \u001b[0;34m\u001b[0m\u001b[0m\n\u001b[1;32m    229\u001b[0m     \u001b[0;32mdef\u001b[0m \u001b[0memit_until_response\u001b[0m\u001b[0;34m(\u001b[0m\u001b[0mself\u001b[0m\u001b[0;34m,\u001b[0m \u001b[0mevent_name\u001b[0m\u001b[0;34m,\u001b[0m \u001b[0;34m**\u001b[0m\u001b[0mkwargs\u001b[0m\u001b[0;34m)\u001b[0m\u001b[0;34m:\u001b[0m\u001b[0;34m\u001b[0m\u001b[0m\n",
      "\u001b[0;32m/Users/aymericflaisler/anaconda2/envs/py27conda/lib/python2.7/site-packages/botocore/hooks.pyc\u001b[0m in \u001b[0;36m_emit\u001b[0;34m(self, event_name, kwargs, stop_on_response)\u001b[0m\n\u001b[1;32m    208\u001b[0m         \u001b[0;32mfor\u001b[0m \u001b[0mhandler\u001b[0m \u001b[0;32min\u001b[0m \u001b[0mhandlers_to_call\u001b[0m\u001b[0;34m:\u001b[0m\u001b[0;34m\u001b[0m\u001b[0m\n\u001b[1;32m    209\u001b[0m             \u001b[0mlogger\u001b[0m\u001b[0;34m.\u001b[0m\u001b[0mdebug\u001b[0m\u001b[0;34m(\u001b[0m\u001b[0;34m'Event %s: calling handler %s'\u001b[0m\u001b[0;34m,\u001b[0m \u001b[0mevent_name\u001b[0m\u001b[0;34m,\u001b[0m \u001b[0mhandler\u001b[0m\u001b[0;34m)\u001b[0m\u001b[0;34m\u001b[0m\u001b[0m\n\u001b[0;32m--> 210\u001b[0;31m             \u001b[0mresponse\u001b[0m \u001b[0;34m=\u001b[0m \u001b[0mhandler\u001b[0m\u001b[0;34m(\u001b[0m\u001b[0;34m**\u001b[0m\u001b[0mkwargs\u001b[0m\u001b[0;34m)\u001b[0m\u001b[0;34m\u001b[0m\u001b[0m\n\u001b[0m\u001b[1;32m    211\u001b[0m             \u001b[0mresponses\u001b[0m\u001b[0;34m.\u001b[0m\u001b[0mappend\u001b[0m\u001b[0;34m(\u001b[0m\u001b[0;34m(\u001b[0m\u001b[0mhandler\u001b[0m\u001b[0;34m,\u001b[0m \u001b[0mresponse\u001b[0m\u001b[0;34m)\u001b[0m\u001b[0;34m)\u001b[0m\u001b[0;34m\u001b[0m\u001b[0m\n\u001b[1;32m    212\u001b[0m             \u001b[0;32mif\u001b[0m \u001b[0mstop_on_response\u001b[0m \u001b[0;32mand\u001b[0m \u001b[0mresponse\u001b[0m \u001b[0;32mis\u001b[0m \u001b[0;32mnot\u001b[0m \u001b[0mNone\u001b[0m\u001b[0;34m:\u001b[0m\u001b[0;34m\u001b[0m\u001b[0m\n",
      "\u001b[0;32m/Users/aymericflaisler/anaconda2/envs/py27conda/lib/python2.7/site-packages/botocore/retryhandler.pyc\u001b[0m in \u001b[0;36m__call__\u001b[0;34m(self, attempts, response, caught_exception, **kwargs)\u001b[0m\n\u001b[1;32m    181\u001b[0m \u001b[0;34m\u001b[0m\u001b[0m\n\u001b[1;32m    182\u001b[0m         \"\"\"\n\u001b[0;32m--> 183\u001b[0;31m         \u001b[0;32mif\u001b[0m \u001b[0mself\u001b[0m\u001b[0;34m.\u001b[0m\u001b[0m_checker\u001b[0m\u001b[0;34m(\u001b[0m\u001b[0mattempts\u001b[0m\u001b[0;34m,\u001b[0m \u001b[0mresponse\u001b[0m\u001b[0;34m,\u001b[0m \u001b[0mcaught_exception\u001b[0m\u001b[0;34m)\u001b[0m\u001b[0;34m:\u001b[0m\u001b[0;34m\u001b[0m\u001b[0m\n\u001b[0m\u001b[1;32m    184\u001b[0m             \u001b[0mresult\u001b[0m \u001b[0;34m=\u001b[0m \u001b[0mself\u001b[0m\u001b[0;34m.\u001b[0m\u001b[0m_action\u001b[0m\u001b[0;34m(\u001b[0m\u001b[0mattempts\u001b[0m\u001b[0;34m=\u001b[0m\u001b[0mattempts\u001b[0m\u001b[0;34m)\u001b[0m\u001b[0;34m\u001b[0m\u001b[0m\n\u001b[1;32m    185\u001b[0m             \u001b[0mlogger\u001b[0m\u001b[0;34m.\u001b[0m\u001b[0mdebug\u001b[0m\u001b[0;34m(\u001b[0m\u001b[0;34m\"Retry needed, action of: %s\"\u001b[0m\u001b[0;34m,\u001b[0m \u001b[0mresult\u001b[0m\u001b[0;34m)\u001b[0m\u001b[0;34m\u001b[0m\u001b[0m\n",
      "\u001b[0;32m/Users/aymericflaisler/anaconda2/envs/py27conda/lib/python2.7/site-packages/botocore/retryhandler.pyc\u001b[0m in \u001b[0;36m__call__\u001b[0;34m(self, attempt_number, response, caught_exception)\u001b[0m\n\u001b[1;32m    249\u001b[0m     \u001b[0;32mdef\u001b[0m \u001b[0m__call__\u001b[0m\u001b[0;34m(\u001b[0m\u001b[0mself\u001b[0m\u001b[0;34m,\u001b[0m \u001b[0mattempt_number\u001b[0m\u001b[0;34m,\u001b[0m \u001b[0mresponse\u001b[0m\u001b[0;34m,\u001b[0m \u001b[0mcaught_exception\u001b[0m\u001b[0;34m)\u001b[0m\u001b[0;34m:\u001b[0m\u001b[0;34m\u001b[0m\u001b[0m\n\u001b[1;32m    250\u001b[0m         should_retry = self._should_retry(attempt_number, response,\n\u001b[0;32m--> 251\u001b[0;31m                                           caught_exception)\n\u001b[0m\u001b[1;32m    252\u001b[0m         \u001b[0;32mif\u001b[0m \u001b[0mshould_retry\u001b[0m\u001b[0;34m:\u001b[0m\u001b[0;34m\u001b[0m\u001b[0m\n\u001b[1;32m    253\u001b[0m             \u001b[0;32mif\u001b[0m \u001b[0mattempt_number\u001b[0m \u001b[0;34m>=\u001b[0m \u001b[0mself\u001b[0m\u001b[0;34m.\u001b[0m\u001b[0m_max_attempts\u001b[0m\u001b[0;34m:\u001b[0m\u001b[0;34m\u001b[0m\u001b[0m\n",
      "\u001b[0;32m/Users/aymericflaisler/anaconda2/envs/py27conda/lib/python2.7/site-packages/botocore/retryhandler.pyc\u001b[0m in \u001b[0;36m_should_retry\u001b[0;34m(self, attempt_number, response, caught_exception)\u001b[0m\n\u001b[1;32m    275\u001b[0m             \u001b[0;31m# If we've exceeded the max attempts we just let the exception\u001b[0m\u001b[0;34m\u001b[0m\u001b[0;34m\u001b[0m\u001b[0m\n\u001b[1;32m    276\u001b[0m             \u001b[0;31m# propogate if one has occurred.\u001b[0m\u001b[0;34m\u001b[0m\u001b[0;34m\u001b[0m\u001b[0m\n\u001b[0;32m--> 277\u001b[0;31m             \u001b[0;32mreturn\u001b[0m \u001b[0mself\u001b[0m\u001b[0;34m.\u001b[0m\u001b[0m_checker\u001b[0m\u001b[0;34m(\u001b[0m\u001b[0mattempt_number\u001b[0m\u001b[0;34m,\u001b[0m \u001b[0mresponse\u001b[0m\u001b[0;34m,\u001b[0m \u001b[0mcaught_exception\u001b[0m\u001b[0;34m)\u001b[0m\u001b[0;34m\u001b[0m\u001b[0m\n\u001b[0m\u001b[1;32m    278\u001b[0m \u001b[0;34m\u001b[0m\u001b[0m\n\u001b[1;32m    279\u001b[0m \u001b[0;34m\u001b[0m\u001b[0m\n",
      "\u001b[0;32m/Users/aymericflaisler/anaconda2/envs/py27conda/lib/python2.7/site-packages/botocore/retryhandler.pyc\u001b[0m in \u001b[0;36m__call__\u001b[0;34m(self, attempt_number, response, caught_exception)\u001b[0m\n\u001b[1;32m    315\u001b[0m         \u001b[0;32mfor\u001b[0m \u001b[0mchecker\u001b[0m \u001b[0;32min\u001b[0m \u001b[0mself\u001b[0m\u001b[0;34m.\u001b[0m\u001b[0m_checkers\u001b[0m\u001b[0;34m:\u001b[0m\u001b[0;34m\u001b[0m\u001b[0m\n\u001b[1;32m    316\u001b[0m             checker_response = checker(attempt_number, response,\n\u001b[0;32m--> 317\u001b[0;31m                                        caught_exception)\n\u001b[0m\u001b[1;32m    318\u001b[0m             \u001b[0;32mif\u001b[0m \u001b[0mchecker_response\u001b[0m\u001b[0;34m:\u001b[0m\u001b[0;34m\u001b[0m\u001b[0m\n\u001b[1;32m    319\u001b[0m                 \u001b[0;32mreturn\u001b[0m \u001b[0mchecker_response\u001b[0m\u001b[0;34m\u001b[0m\u001b[0m\n",
      "\u001b[0;32m/Users/aymericflaisler/anaconda2/envs/py27conda/lib/python2.7/site-packages/botocore/retryhandler.pyc\u001b[0m in \u001b[0;36m__call__\u001b[0;34m(self, attempt_number, response, caught_exception)\u001b[0m\n\u001b[1;32m    221\u001b[0m         \u001b[0;32melif\u001b[0m \u001b[0mcaught_exception\u001b[0m \u001b[0;32mis\u001b[0m \u001b[0;32mnot\u001b[0m \u001b[0mNone\u001b[0m\u001b[0;34m:\u001b[0m\u001b[0;34m\u001b[0m\u001b[0m\n\u001b[1;32m    222\u001b[0m             return self._check_caught_exception(\n\u001b[0;32m--> 223\u001b[0;31m                 attempt_number, caught_exception)\n\u001b[0m\u001b[1;32m    224\u001b[0m         \u001b[0;32melse\u001b[0m\u001b[0;34m:\u001b[0m\u001b[0;34m\u001b[0m\u001b[0m\n\u001b[1;32m    225\u001b[0m             \u001b[0;32mraise\u001b[0m \u001b[0mValueError\u001b[0m\u001b[0;34m(\u001b[0m\u001b[0;34m\"Both response and caught_exception are None.\"\u001b[0m\u001b[0;34m)\u001b[0m\u001b[0;34m\u001b[0m\u001b[0m\n",
      "\u001b[0;32m/Users/aymericflaisler/anaconda2/envs/py27conda/lib/python2.7/site-packages/botocore/retryhandler.pyc\u001b[0m in \u001b[0;36m_check_caught_exception\u001b[0;34m(self, attempt_number, caught_exception)\u001b[0m\n\u001b[1;32m    357\u001b[0m         \u001b[0;31m# the MaxAttemptsDecorator is not interested in retrying the exception\u001b[0m\u001b[0;34m\u001b[0m\u001b[0;34m\u001b[0m\u001b[0m\n\u001b[1;32m    358\u001b[0m         \u001b[0;31m# then this exception just propogates out past the retry code.\u001b[0m\u001b[0;34m\u001b[0m\u001b[0;34m\u001b[0m\u001b[0m\n\u001b[0;32m--> 359\u001b[0;31m         \u001b[0;32mraise\u001b[0m \u001b[0mcaught_exception\u001b[0m\u001b[0;34m\u001b[0m\u001b[0m\n\u001b[0m",
      "\u001b[0;31mEndpointConnectionError\u001b[0m: Could not connect to the endpoint URL: \"https://s3.ireland.amazonaws.com/ai-sony-automation?encoding-type=url\""
     ]
    }
   ],
   "source": [
    "t.list_objects(Bucket='ai-sony-automation')"
   ]
  },
  {
   "cell_type": "code",
   "execution_count": null,
   "metadata": {
    "collapsed": true
   },
   "outputs": [],
   "source": []
  }
 ],
 "metadata": {
  "kernelspec": {
   "display_name": "Python 2",
   "language": "python",
   "name": "python2"
  },
  "language_info": {
   "codemirror_mode": {
    "name": "ipython",
    "version": 2
   },
   "file_extension": ".py",
   "mimetype": "text/x-python",
   "name": "python",
   "nbconvert_exporter": "python",
   "pygments_lexer": "ipython2",
   "version": "2.7.13"
  }
 },
 "nbformat": 4,
 "nbformat_minor": 2
}
